<?xml version="1.0" ?>
<sdf version="1.9">
  <model name="drone">

    <static>false</static>

    <!-- ===================================================== -->
    <!--                    BASE LINK                         -->
    <!-- ===================================================== -->
    <link name="base_link">
      <pose>0 0 0 0 0 0</pose>

      <inertial>
        <mass>1.3116</mass>
        <inertia>
          <ixx>0.003708</ixx>
          <iyy>0.002511</iyy>
          <izz>0.004013</izz>
          <ixy>0</ixy>
          <ixz>-2e-06</ixz>
          <iyz>-1.7e-05</iyz>
        </inertia>
      </inertial>

      <visual name="base_visual">
        <geometry>
          <mesh>
            <scale>0.1 0.1 0.1</scale>
            <uri>model://drone/meshes/drone.obj</uri>
          </mesh>
        </geometry>
      </visual>

      <collision name="base_collision">
        <geometry>
          <box><size>0.20 0.20 0.06</size></box>
        </geometry>
      </collision>

      <!-- ===================================================== -->
      <!--                        SENSORS                       -->
      <!-- ===================================================== -->

      <!-- IMU (MPU6000 noise approximation) -->
      <sensor name="imu_sensor" type="imu">
        <always_on>true</always_on>
        <update_rate>250</update_rate>
        <imu>
          <angular_velocity>
            <noise type="gaussian">
              <mean>0.0</mean>
              <stddev>0.0014</stddev>
            </noise>
          </angular_velocity>
          <linear_acceleration>
            <noise type="gaussian">
              <mean>0.0</mean>
              <stddev>0.03</stddev>
            </noise>
          </linear_acceleration>
        </imu>
      </sensor>

      <!-- Magnetometer -->
      <sensor name="magnetometer_sensor" type="magnetometer">
        <always_on>true</always_on>
        <update_rate>100</update_rate>
        <magnetometer>
          <x><noise type="gaussian"><stddev>0.0001</stddev></noise></x>
          <y><noise type="gaussian"><stddev>0.0001</stddev></noise></y>
          <z><noise type="gaussian"><stddev>0.0001</stddev></noise></z>
        </magnetometer>
      </sensor>

      <!-- Barometer (BMP280) -->
      <sensor name="barometer_sensor" type="air_pressure">
        <always_on>true</always_on>
        <update_rate>50</update_rate>
        <air_pressure>
          <pressure>
            <noise type="gaussian">
              <mean>0</mean>
              <stddev>1.3</stddev>
            </noise>
          </pressure>
        </air_pressure>
      </sensor>

      <!-- GPS (Enabled, needed for Offboard / ALTCTL / POSCTL in SITL) -->
      <sensor name="gps_sensor" type="navsat">
        <always_on>true</always_on>
        <update_rate>10</update_rate>
        <navsat>
          <position>
            <noise type="gaussian"><stddev>0.7</stddev></noise>
          </position>
          <velocity>
            <noise type="gaussian"><stddev>0.1</stddev></noise>
          </velocity>
        </navsat>
      </sensor>

      <!-- ===================================================== -->
      <!--                      CAMERA                          -->
      <!-- ===================================================== -->
      <!-- IMX219 Wide Lens (155° H, 115° V) | No distortion yet -->
      <sensor name="front_camera" type="camera">
        <always_on>true</always_on>
        <update_rate>30</update_rate>

        <pose>0.05 0.0 0.03 0 0 0</pose> <!-- Forward, slightly forward-mount -->

        <camera>
          <horizontal_fov>2.705</horizontal_fov> <!-- ≈155° -->
          <image>
            <width>640</width>
            <height>480</height>
            <format>R8G8B8</format>
          </image>
          <clip><near>0.01</near><far>100</far></clip>
          <lens>
            <type>equidistant</type> <!-- Matches fisheye projection -->
            <scale_to_hfov>true</scale_to_hfov>
          </lens>
        </camera>

        <topic>/drone/camera/image_raw</topic>
      </sensor>

    </link>

    <!-- ===================================================== -->
    <!--                      ROTOR LINKS                      -->
    <!-- ===================================================== -->
    <link name="rotor_0"><pose>0.05 0.05 0.02 0 0 0</pose><inertial><mass>0.01</mass><inertia><ixx>1e-6</ixx><iyy>1e-6</iyy><izz>1e-6</izz></inertia></inertial></link>
    <joint name="rotor_0_joint" type="revolute"><parent>base_link</parent><child>rotor_0</child><axis><xyz>0 0 1</xyz></axis></joint>

    <link name="rotor_1"><pose>-0.05 0.05 0.02 0 0 0</pose><inertial><mass>0.01</mass><inertia><ixx>1e-6</ixx><iyy>1e-6</iyy><izz>1e-6</izz></inertia></inertial></link>
    <joint name="rotor_1_joint" type="revolute"><parent>base_link</parent><child>rotor_1</child><axis><xyz>0 0 1</xyz></axis></joint>

    <link name="rotor_2"><pose>-0.05 -0.05 0.02 0 0 0</pose><inertial><mass>0.01</mass><inertia><ixx>1e-6</ixx><iyy>1e-6</iyy><izz>1e-6</izz></inertia></inertial></link>
    <joint name="rotor_2_joint" type="revolute"><parent>base_link</parent><child>rotor_2</child><axis><xyz>0 0 1</xyz></axis></joint>

    <link name="rotor_3"><pose>0.05 -0.05 0.02 0 0 0</pose><inertial><mass>0.01</mass><inertia><ixx>1e-6</ixx><iyy>1e-6</iyy><izz>1e-6</izz></inertia></inertial></link>
    <joint name="rotor_3_joint" type="revolute"><parent>base_link</parent><child>rotor_3</child><axis><xyz>0 0 1</xyz></axis></joint>

    <!-- ===================================================== -->
    <!--                  MOTOR MODELS                         -->
    <!-- ===================================================== -->
    <plugin filename="gz-sim-multicopter-motor-model-system"
            name="gz::sim::systems::MulticopterMotorModel">
      <motorNumber>0</motorNumber>
      <jointName>rotor_0_joint</jointName>
      <linkName>rotor_0</linkName>
      <turningDirection>ccw</turningDirection>
      <commandSubTopic>command/motor_speed</commandSubTopic>
      <maxRotVelocity>4000</maxRotVelocity>
      <motorConstant>2.0e-7</motorConstant>
      <momentConstant>0.006</momentConstant>
      <rotorDragCoefficient>8.06428e-05</rotorDragCoefficient>
      <rollingMomentCoefficient>1e-06</rollingMomentCoefficient>
      <rotorVelocitySlowdownSim>10</rotorVelocitySlowdownSim>
      <timeConstantUp>0.005</timeConstantUp>
      <timeConstantDown>0.010</timeConstantDown>
      <motorType>velocity</motorType>
    </plugin>

    <plugin filename="gz-sim-multicopter-motor-model-system"
            name="gz::sim::systems::MulticopterMotorModel">
      <motorNumber>1</motorNumber>
      <jointName>rotor_1_joint</jointName>
      <linkName>rotor_1</linkName>
      <turningDirection>cw</turningDirection>
      <commandSubTopic>command/motor_speed</commandSubTopic>
      <maxRotVelocity>4000</maxRotVelocity>
      <motorConstant>2.0e-7</motorConstant>
      <momentConstant>0.006</momentConstant>
      <rotorDragCoefficient>8.06428e-05</rotorDragCoefficient>
      <rollingMomentCoefficient>1e-06</rollingMomentCoefficient>
      <rotorVelocitySlowdownSim>10</rotorVelocitySlowdownSim>
      <timeConstantUp>0.005</timeConstantUp>
      <timeConstantDown>0.010</timeConstantDown>
      <motorType>velocity</motorType>
    </plugin>

    <plugin filename="gz-sim-multicopter-motor-model-system"
            name="gz::sim::systems::MulticopterMotorModel">
      <motorNumber>2</motorNumber>
      <jointName>rotor_2_joint</jointName>
      <linkName>rotor_2</linkName>
      <turningDirection>ccw</turningDirection>
      <commandSubTopic>command/motor_speed</commandSubTopic>
      <maxRotVelocity>4000</maxRotVelocity>
      <motorConstant>2.0e-7</motorConstant>
      <momentConstant>0.006</momentConstant>
      <rotorDragCoefficient>8.06428e-05</rotorDragCoefficient>
      <rollingMomentCoefficient>1e-06</rollingMomentCoefficient>
      <rotorVelocitySlowdownSim>10</rotorVelocitySlowdownSim>
      <timeConstantUp>0.005</timeConstantUp>
      <timeConstantDown>0.010</timeConstantDown>
      <motorType>velocity</motorType>
    </plugin>

    <plugin filename="gz-sim-multicopter-motor-model-system"
            name="gz::sim::systems::MulticopterMotorModel">
      <motorNumber>3</motorNumber>
      <jointName>rotor_3_joint</jointName>
      <linkName>rotor_3</linkName>
      <turningDirection>cw</turningDirection>
      <commandSubTopic>command/motor_speed</commandSubTopic>
      <maxRotVelocity>4000</maxRotVelocity>
      <motorConstant>2.0e-7</motorConstant>
      <momentConstant>0.006</momentConstant>
      <rotorDragCoefficient>8.06428e-05</rotorDragCoefficient>
      <rollingMomentCoefficient>1e-06</rollingMomentCoefficient>
      <rotorVelocitySlowdownSim>10</rotorVelocitySlowdownSim>
      <timeConstantUp>0.005</timeConstantUp>
      <timeConstantDown>0.010</timeConstantDown>
      <motorType>velocity</motorType>
    </plugin>

  </model>
</sdf>
