<?xml version="1.0" encoding="UTF-8"?>
<!-- DO NOT EDIT: Generated from tiltrotor.sdf.jinja -->
<sdf version='1.5'>
  <model name='my_tilt_vtol'>
    <pose>0 0 0.246 0 0 0</pose> <!--Gazebo 월드 기준 초기 위치-->
    <link name="base_link">
      <pose>0 0 0 0 0 0</pose>
      <inertial>
        <mass>5.0</mass>
        <inertia> <!--회전 관성 모멘트 기준점이 뭐지?-->
          <ixx>0.197563</ixx>
          <ixy>0</ixy>
          <ixz>0</ixz>
          <iyy>0.1458929</iyy>
          <iyz>0</iyz>
          <izz>0.1477</izz>
        </inertia>
      </inertial>

      <collision name='base_link_collision'> <!--충돌 박스를 둠, 외형 메쉬 그대로 collision 쓰면 연산량 폭증, 불안정 등 현상 발생 가능성 있음.-->
        <pose>-0.01 0 -0.08 0 0 0</pose>
        <geometry>
          <box>
            <size>0.55 2.144 0.05</size>
          </box>
        </geometry>
        <surface> <!--지면 접촉 충돌(착륙 시 튕김 관련 정보?)-->
          <contact>
            <ode>
              <kp>100000</kp>
              <kd>1.0</kd>
              <max_vel>0.1</max_vel>
              <min_depth>0.001</min_depth>
            </ode>
          </contact>
          <friction>
            <ode />
          </friction>
        </surface>
      </collision>

      <!-- body mesh -->
      <visual name='base_link_visual'> <!--외형-->
        <pose>0 0 0 0 0 0</pose>
        <geometry>
          <mesh>
            <uri>model://my_tilt_vtol/meshes/U60_Body.dae</uri>
            <scale>1 1 1</scale>
          </mesh>
        </geometry>
        <material> <!-- DarkGrey-->
          <ambient>0.175 0.175 0.175 1.0</ambient>
          <diffuse>0.175 0.175 0.175 1.0</diffuse>
        </material>
      </visual>
      <sensor name="imu_sensor" type="imu"> <!--PX4 EKF가 사용하는 IMU-->
        <gz_frame_id>base_link</gz_frame_id>
        <always_on>1</always_on>
        <update_rate>250</update_rate>
        <imu>
          <angular_velocity>
            <x>
              <noise type="gaussian">
                <mean>0</mean>
                <stddev>0.0003394</stddev>
                <dynamic_bias_stddev>3.8785e-05</dynamic_bias_stddev>
                <dynamic_bias_correlation_time>1000</dynamic_bias_correlation_time>
              </noise>
            </x>
            <y>
              <noise type="gaussian">
                <mean>0</mean>
                <stddev>0.0003394</stddev>
                <dynamic_bias_stddev>3.8785e-05</dynamic_bias_stddev>
                <dynamic_bias_correlation_time>1000</dynamic_bias_correlation_time>
              </noise>
            </y>
            <z>
              <noise type="gaussian">
                <mean>0</mean>
                <stddev>0.0003394</stddev>
                <dynamic_bias_stddev>3.8785e-05</dynamic_bias_stddev>
                <dynamic_bias_correlation_time>1000</dynamic_bias_correlation_time>
              </noise>
            </z>
          </angular_velocity>
          <linear_acceleration>
            <x>
              <noise type="gaussian">
                <mean>0</mean>
                <stddev>0.004</stddev>
                <dynamic_bias_stddev>0.006</dynamic_bias_stddev>
                <dynamic_bias_correlation_time>300</dynamic_bias_correlation_time>
              </noise>
            </x>
            <y>
              <noise type="gaussian">
                <mean>0</mean>
                <stddev>0.004</stddev>
                <dynamic_bias_stddev>0.006</dynamic_bias_stddev>
                <dynamic_bias_correlation_time>300</dynamic_bias_correlation_time>
              </noise>
            </y>
            <z>
              <noise type="gaussian">
                <mean>0</mean>
                <stddev>0.004</stddev>
                <dynamic_bias_stddev>0.006</dynamic_bias_stddev>
                <dynamic_bias_correlation_time>300</dynamic_bias_correlation_time>
              </noise>
            </z>
          </linear_acceleration>
        </imu>
      </sensor>
      <sensor name="air_pressure_sensor" type="air_pressure">
        <gz_frame_id>base_link</gz_frame_id>
        <always_on>1</always_on>
        <update_rate>50</update_rate>
        <air_pressure>
          <pressure>
            <noise type="gaussian">
              <mean>0</mean>
              <stddev>0.01</stddev>
            </noise>
          </pressure>
        </air_pressure>
      </sensor>
      <sensor name="magnetometer_sensor" type="magnetometer">
        <gz_frame_id>base_link</gz_frame_id>
        <always_on>1</always_on>
        <update_rate>100</update_rate>
        <magnetometer>
          <!-- TODO: update to fix units and coordinate system when we move past Harmonic -->
          <!-- See https://github.com/gazebosim/gz-sim/pull/2460 -->
          <!-- 3mgauss RMS: NOTE: noise is in tesla but sensor reports data in gauss -->
          <!-- Noise modeled after IIS2MDC -->
          <x>
            <noise type="gaussian">
              <stddev>0.0001</stddev>
            </noise>
          </x>
          <y>
            <noise type="gaussian">
              <stddev>0.0001</stddev>
            </noise>
          </y>
          <z>
            <noise type="gaussian">
              <stddev>0.0001</stddev>
            </noise>
          </z>
        </magnetometer>
      </sensor>
      <sensor name="navsat_sensor" type="navsat">
        <gz_frame_id>base_link</gz_frame_id>
        <always_on>1</always_on>
        <update_rate>30</update_rate>
      </sensor>
    </link>

    <include merge="true">
      <uri>model://airspeed</uri>
      <pose>0. 0. 0. 0. 0. 0.</pose>
    </include>
    <joint name='airspeed_joint' type='fixed'>
      <parent>base_link</parent>
      <child>airspeed_link</child>
      <pose relative_to="base_link">-0 0 0 0 0 0</pose>
    </joint>

    <!-- ========================= -->
    <!-- ======== FR MOTOR ======= -->
    <!-- ========================= -->
    <link name="motor_0">
      <!-- base_link 기준 위치 -->
      <pose>0 0 0.025 0 0 0</pose>
      <inertial>
        <mass>0.05</mass>
        <inertia> <!--모터 중심에서 모터 끝까지?-->
          <ixx>0.0166704</ixx>
          <ixy>0</ixy>
          <ixz>0</ixz>
          <iyy>0.0166704</iyy>
          <iyz>0</iyz>
          <izz>0.0167604</izz>
        </inertia>
      </inertial>
      <collision name="motor_0_collision">
        <geometry>
          <cylinder> <!--모터 실린거 사이즈 필요. 이게 뭔데?-->
            <length>0.035</length>
            <radius>0.02</radius>
          </cylinder>
        </geometry>
        <surface>
          <contact>
            <ode />
          </contact>
          <friction>
            <ode />
          </friction>
        </surface>
      </collision>

      <visual name="motor_0_visual">
        <geometry>
          <mesh>
            <scale>1 1 1</scale>
            <uri>model://my_tilt_vtol/meshes/U60_FR_Ducted.dae</uri>
          </mesh>
        </geometry>
        <material>
          <ambient>0.175 0.175 0.175 1.0</ambient>
          <diffuse>0.175 0.175 0.175 1.0</diffuse>
        </material>
      </visual>
      <gravity>1</gravity>
      <velocity_decay />
      <self_collide>0</self_collide>
    </link>

    <joint name='motor_0_joint' type='revolute'>
      <child>motor_0</child>
      <parent>base_link</parent>
      <axis>
        <xyz>0 1 0</xyz> <!--Y축 기준 회전 (틸트로터)-->
        <limit>
          <lower>0.</lower>
          <upper>1.57</upper> <!--0도 ~ 90도-->
        </limit>
        <dynamics> <!--dynamic 부분 수정 필요-->
          <friction>1.0</friction>
          <spring_reference>0</spring_reference>
          <spring_stiffness>0</spring_stiffness>
        </dynamics>
        <use_parent_model_frame>1</use_parent_model_frame>
      </axis>
    </joint>

    <!-- ========================= -->
    <!-- ======== FR ROTOR ======= -->
    <!-- ========================= -->
    <link name="rotor_0">
      <!-- motor 기준 상대 위치 -->
      <pose>0 0 0.025 0 0 0</pose>

      <inertial>
        <pose>0 0 0 0 0 0</pose>
        <mass>0.005</mass>
        <inertia>
          <ixx>9.75e-07</ixx>
          <ixy>0</ixy>
          <ixz>0</ixz>
          <iyy>0.000166704</iyy>
          <iyz>0</iyz>
          <izz>0.000167604</izz>
        </inertia>
      </inertial>

      <collision name="rotor_0_collision">
        <geometry>
          <cylinder>
            <length>0.005</length>
            <radius>0.1</radius>
          </cylinder>
        </geometry>
        <surface>
          <contact>
            <ode />
          </contact>
          <friction>
            <ode />
          </friction>
        </surface>
      </collision>

      <visual name="rotor_0_visual">
        <geometry>
          <mesh>
            <scale>1 1 1</scale>
            <uri>model://my_tilt_vtol/meshes/U60_FR_Rotor.dae</uri> <!--FR 로터 .dae 파일 수정 필요-->
          </mesh>
        </geometry>
        <material>  <!-- Blue -->
          <ambient>0 0 1 1.0</ambient>
          <diffuse>0 0 1 1.0</diffuse>
        </material>
      </visual>
      <gravity>1</gravity>
      <velocity_decay />
      <self_collide>0</self_collide>
    </link>

    <!-- rotor spin joint -->
    <joint name="rotor_0_joint" type="revolute">
      <child>rotor_0</child>
      <parent>motor_0</parent>
      <axis>
        <!-- 회전 축 (Z축) -->
        <xyz>0 0 1</xyz>
        <limit>
          <lower>-1e+16</lower>
          <upper>1e+16</upper>
        </limit>
        <dynamics>
          <spring_reference>0</spring_reference>
          <spring_stiffness>0</spring_stiffness>
        </dynamics>
        <use_parent_model_frame>1</use_parent_model_frame>
      </axis>
    </joint>
    <!-- ========================= -->
    <!-- ======== RR MOTOR ======= -->
    <!-- ========================= -->
    <link name="motor_1">
      <!-- base_link 기준 위치 -->
      <pose>0 0 0.025 0 0 0</pose>
      <inertial>
        <mass>0.05</mass>
        <inertia> <!--모터 중심에서 모터 끝까지?-->
          <ixx>0.0166704</ixx>
          <ixy>0</ixy>
          <ixz>0</ixz>
          <iyy>0.0166704</iyy>
          <iyz>0</iyz>
          <izz>0.0167604</izz>
        </inertia>
      </inertial>
      <collision name="motor_1_collision">
        <geometry>
          <cylinder> <!--모터 실린거 사이즈 필요. 이게 뭔데?-->
            <length>0.035</length>
            <radius>0.02</radius>
          </cylinder>
        </geometry>
        <surface>
          <contact>
            <ode />
          </contact>
          <friction>
            <ode />
          </friction>
        </surface>
      </collision>

      <visual name="motor_1_visual">
        <geometry>
          <mesh>
            <scale>1 1 1</scale>
            <uri>model://my_tilt_vtol/meshes/U60_RR_Ducted.dae</uri>
          </mesh>
        </geometry>
        <material>
          <ambient>0.175 0.175 0.175 1.0</ambient>
          <diffuse>0.175 0.175 0.175 1.0</diffuse>
        </material>
      </visual>
      <gravity>1</gravity>
      <velocity_decay />
      <self_collide>0</self_collide>
    </link>

    <joint name='motor_1_joint' type='revolute'>
      <child>motor_1</child>
      <parent>base_link</parent>
      <axis>
        <xyz>0 1 0</xyz> <!--Y축 기준 회전 (틸트로터)-->
        <limit>
          <lower>0.</lower>
          <upper>1.57</upper> <!--0도 ~ 90도-->
        </limit>
        <dynamics> <!--dynamic 부분 수정 필요-->
          <friction>1.0</friction>
          <spring_reference>0</spring_reference>
          <spring_stiffness>0</spring_stiffness>
        </dynamics>
        <use_parent_model_frame>1</use_parent_model_frame>
      </axis>
    </joint>

    <!-- ========================= -->
    <!-- ======== RR ROTOR ======= -->
    <!-- ========================= -->
    <link name="rotor_1">
      <!-- motor 기준 상대 위치 -->
      <pose>0 0 0.025 0 0 0</pose>

      <inertial>
        <pose>0 0 0 0 0 0</pose>
        <mass>0.005</mass>
        <inertia>
          <ixx>9.75e-07</ixx>
          <ixy>0</ixy>
          <ixz>0</ixz>
          <iyy>0.000166704</iyy>
          <iyz>0</iyz>
          <izz>0.000167604</izz>
        </inertia>
      </inertial>

      <collision name="rotor_1_collision">
        <geometry>
          <cylinder>
            <length>0.005</length>
            <radius>0.1</radius>
          </cylinder>
        </geometry>
        <surface>
          <contact>
            <ode />
          </contact>
          <friction>
            <ode />
          </friction>
        </surface>
      </collision>

      <visual name="rotor_1_visual">
        <geometry>
          <mesh>
            <scale>1 1 1</scale>
            <uri>model://my_tilt_vtol/meshes/U60_RR_Rotor.dae</uri>
          </mesh>
        </geometry>
        <material>  <!-- Blue -->
          <ambient>0 0 1 1.0</ambient>
          <diffuse>0 0 1 1.0</diffuse>
        </material>
      </visual>
      <gravity>1</gravity>
      <velocity_decay />
      <self_collide>0</self_collide>
    </link>

    <!-- rotor spin joint -->
    <joint name="rotor_1_joint" type="revolute">
      <child>rotor_1</child>
      <parent>motor_1</parent>
      <axis>
        <!-- 회전 축 (Z축) -->
        <xyz>0 0 1</xyz>
        <limit>
          <lower>-1e+16</lower>
          <upper>1e+16</upper>
        </limit>
        <dynamics>
          <spring_reference>0</spring_reference>
          <spring_stiffness>0</spring_stiffness>
        </dynamics>
        <use_parent_model_frame>1</use_parent_model_frame>
      </axis>
    </joint>

    <!-- ========================= -->
    <!-- ======== RL MOTOR ======= -->
    <!-- ========================= -->
    <link name="motor_2">
      <!-- base_link 기준 위치 -->
      <pose>0 0 0.025 0 0 0</pose>
      <inertial>
        <mass>0.05</mass>
        <inertia> <!--모터 중심에서 모터 끝까지?-->
          <ixx>0.0166704</ixx>
          <ixy>0</ixy>
          <ixz>0</ixz>
          <iyy>0.0166704</iyy>
          <iyz>0</iyz>
          <izz>0.0167604</izz>
        </inertia>
      </inertial>
      <collision name="motor_2_collision">
        <geometry>
          <cylinder> <!--모터 실린거 사이즈 필요. 이게 뭔데?-->
            <length>0.035</length>
            <radius>0.02</radius>
          </cylinder>
        </geometry>
        <surface>
          <contact>
            <ode />
          </contact>
          <friction>
            <ode />
          </friction>
        </surface>
      </collision>

      <visual name="motor_2_visual">
        <geometry>
          <mesh>
            <scale>1 1 1</scale>
            <uri>model://my_tilt_vtol/meshes/U60_RL_Ducted.dae</uri>
          </mesh>
        </geometry>
        <material>
          <ambient>0.175 0.175 0.175 1.0</ambient>
          <diffuse>0.175 0.175 0.175 1.0</diffuse>
        </material>
      </visual>
      <gravity>1</gravity>
      <velocity_decay />
      <self_collide>0</self_collide>
    </link>

    <joint name='motor_2_joint' type='revolute'>
      <child>motor_2</child>
      <parent>base_link</parent>
      <axis>
        <xyz>0 1 0</xyz> <!--Y축 기준 회전 (틸트로터)-->
        <limit>
          <lower>0.</lower>
          <upper>1.57</upper> <!--0도 ~ 90도-->
        </limit>
        <dynamics> <!--dynamic 부분 수정 필요-->
          <friction>1.0</friction>
          <spring_reference>0</spring_reference>
          <spring_stiffness>0</spring_stiffness>
        </dynamics>
        <use_parent_model_frame>1</use_parent_model_frame>
      </axis>
    </joint>

    <!-- ========================= -->
    <!-- ======== RL ROTOR ======= -->
    <!-- ========================= -->
    <link name="rotor_2">
      <!-- motor 기준 상대 위치 -->
      <pose>0 0 0.025 0 0 0</pose>

      <inertial>
        <pose>0 0 0 0 0 0</pose>
        <mass>0.005</mass>
        <inertia>
          <ixx>9.75e-07</ixx>
          <ixy>0</ixy>
          <ixz>0</ixz>
          <iyy>0.000166704</iyy>
          <iyz>0</iyz>
          <izz>0.000167604</izz>
        </inertia>
      </inertial>

      <collision name="rotor_2_collision">
        <geometry>
          <cylinder>
            <length>0.005</length>
            <radius>0.1</radius>
          </cylinder>
        </geometry>
        <surface>
          <contact>
            <ode />
          </contact>
          <friction>
            <ode />
          </friction>
        </surface>
      </collision>

      <visual name="rotor_2_visual">
        <geometry>
          <mesh>
            <scale>1 1 1</scale>
            <uri>model://my_tilt_vtol/meshes/U60_RL_Rotor.dae</uri>
          </mesh>
        </geometry>
        <material>  <!-- Blue -->
          <ambient>0 0 1 1.0</ambient>
          <diffuse>0 0 1 1.0</diffuse>
        </material>
      </visual>
      <gravity>1</gravity>
      <velocity_decay />
      <self_collide>0</self_collide>
    </link>

    <!-- rotor spin joint -->
    <joint name="rotor_2_joint" type="revolute">
      <child>rotor_2</child>
      <parent>motor_2</parent>
      <axis>
        <!-- 회전 축 (Z축) -->
        <xyz>0 0 1</xyz>
        <limit>
          <lower>-1e+16</lower>
          <upper>1e+16</upper>
        </limit>
        <dynamics>
          <spring_reference>0</spring_reference>
          <spring_stiffness>0</spring_stiffness>
        </dynamics>
        <use_parent_model_frame>1</use_parent_model_frame>
      </axis>
    </joint>

    <!-- ========================= -->
    <!-- ======== FL MOTOR ======= -->
    <!-- ========================= -->
    <link name="motor_3">
      <!-- base_link 기준 위치 -->
      <pose>0 0 0.025 0 0 0</pose>
      <inertial>
        <mass>0.05</mass>
        <inertia> <!--모터 중심에서 모터 끝까지?-->
          <ixx>0.0166704</ixx>
          <ixy>0</ixy>
          <ixz>0</ixz>
          <iyy>0.0166704</iyy>
          <iyz>0</iyz>
          <izz>0.0167604</izz>
        </inertia>
      </inertial>
      <collision name="motor_3_collision">
        <geometry>
          <cylinder> <!--모터 실린거 사이즈 필요. 이게 뭔데?-->
            <length>0.035</length>
            <radius>0.02</radius>
          </cylinder>
        </geometry>
        <surface>
          <contact>
            <ode />
          </contact>
          <friction>
            <ode />
          </friction>
        </surface>
      </collision>

      <visual name="motor_3_visual">
        <geometry>
          <mesh>
            <scale>1 1 1</scale>
            <uri>model://my_tilt_vtol/meshes/U60_FL_Ducted.dae</uri>
          </mesh>
        </geometry>
        <material>
          <ambient>0.175 0.175 0.175 1.0</ambient>
          <diffuse>0.175 0.175 0.175 1.0</diffuse>
        </material>
      </visual>
      <gravity>1</gravity>
      <velocity_decay />
      <self_collide>0</self_collide>
    </link>

    <joint name='motor_3_joint' type='revolute'>
      <child>motor_3</child>
      <parent>base_link</parent>
      <axis>
        <xyz>0 1 0</xyz> <!--Y축 기준 회전 (틸트로터)-->
        <limit>
          <lower>0.</lower>
          <upper>1.57</upper> <!--0도 ~ 90도-->
        </limit>
        <dynamics> <!--dynamic 부분 수정 필요-->
          <friction>1.0</friction>
          <spring_reference>0</spring_reference>
          <spring_stiffness>0</spring_stiffness>
        </dynamics>
        <use_parent_model_frame>1</use_parent_model_frame>
      </axis>
    </joint>

    <!-- ========================= -->
    <!-- ======== FL ROTOR ======= -->
    <!-- ========================= -->
    <link name="rotor_3">
      <!-- motor 기준 상대 위치 -->
      <pose>0 0 0.025 0 0 0</pose>

      <inertial>
        <pose>0 0 0 0 0 0</pose>
        <mass>0.005</mass>
        <inertia>
          <ixx>9.75e-07</ixx>
          <ixy>0</ixy>
          <ixz>0</ixz>
          <iyy>0.000166704</iyy>
          <iyz>0</iyz>
          <izz>0.000167604</izz>
        </inertia>
      </inertial>

      <collision name="rotor_3_collision">
        <geometry>
          <cylinder>
            <length>0.005</length>
            <radius>0.1</radius>
          </cylinder>
        </geometry>
        <surface>
          <contact>
            <ode />
          </contact>
          <friction>
            <ode />
          </friction>
        </surface>
      </collision>

      <visual name="rotor_3_visual">
        <geometry>
          <mesh>
            <scale>1 1 1</scale>
            <uri>model://my_tilt_vtol/meshes/U60_FL_Rotor.dae</uri>
          </mesh>
        </geometry>
        <material>  <!-- Blue -->
          <ambient>0 0 1 1.0</ambient>
          <diffuse>0 0 1 1.0</diffuse>
        </material>
      </visual>
      <gravity>1</gravity>
      <velocity_decay />
      <self_collide>0</self_collide>
    </link>

    <!-- rotor spin joint -->
    <joint name="rotor_3_joint" type="revolute">
      <child>rotor_3</child>
      <parent>motor_3</parent>
      <axis>
        <!-- 회전 축 (Z축) -->
        <xyz>0 0 1</xyz>
        <limit>
          <lower>-1e+16</lower>
          <upper>1e+16</upper>
        </limit>
        <dynamics>
          <spring_reference>0</spring_reference>
          <spring_stiffness>0</spring_stiffness>
        </dynamics>
        <use_parent_model_frame>1</use_parent_model_frame>
      </axis>
    </joint>


    <link name="right_ailerone">
      <!-- base_link 기준 위치 -->
      <inertial>
        <mass>0.001</mass>
        <inertia>
          <ixx>1e-5</ixx>
          <ixy>0.0</ixy>
          <iyy>1e-5</iyy>
          <ixz>0.0</ixz>
          <iyz>0.0</iyz>
          <izz>1e-5</izz>
        </inertia>
      </inertial>


      <visual name="right_ailerone_visual">
        <geometry>
          <mesh>
            <scale>1 1 1</scale>
            <uri>model://my_tilt_vtol/meshes/U60_Right_Aileron.dae</uri>
          </mesh>
        </geometry>
        <material>  <!-- Blue -->
          <ambient>0 1 1 1.0</ambient>
          <diffuse>0 1 1 1.0</diffuse>
        </material>
      </visual>
      <gravity>1</gravity>
      <velocity_decay />
      <self_collide>0</self_collide>
    </link>

    <joint name='right_ailerone_joint' type='revolute'>
      <child>right_ailerone</child>
      <parent>base_link</parent>
      <axis>
        <xyz>0 1 0</xyz> <!--Y축 기준 회전 (틸트로터)-->
        <limit>
          <lower>-0.78</lower>
          <upper>0.78</upper>
        </limit>
        <dynamics>
          <damping>1.000</damping>
        </dynamics>
      </axis>
    </joint>

    <link name="left_ailerone">
      <!-- base_link 기준 위치 -->
      <inertial>
        <mass>0.001</mass>
        <inertia>
          <ixx>1e-5</ixx>
          <ixy>0.0</ixy>
          <iyy>1e-5</iyy>
          <ixz>0.0</ixz>
          <iyz>0.0</iyz>
          <izz>1e-5</izz>
        </inertia>
      </inertial>

    <visual name="left_ailerone_visual">
        <geometry>
          <mesh>
            <scale>1 1 1</scale>
            <uri>model://my_tilt_vtol/meshes/U60_Left_Aileron.dae</uri>
          </mesh>
        </geometry>
        <material>  <!-- Blue -->
          <ambient>0 1 1 1.0</ambient>
          <diffuse>0 1 1 1.0</diffuse>
        </material>
      </visual>
      <gravity>1</gravity>
      <velocity_decay />
      <self_collide>0</self_collide>
    </link>

    <joint name='left_ailerone_joint' type='revolute'>
      <child>left_ailerone</child>
      <parent>base_link</parent>
      <axis>
        <xyz>0 1 0</xyz> <!--Y축 기준 회전 (틸트로터)-->
        <limit>
          <lower>-0.78</lower>
          <upper>0.78</upper>
        </limit>
        <dynamics>
          <damping>1.000</damping>
        </dynamics>
      </axis>
    </joint>



    <link name="right_flap">
      <!-- base_link 기준 위치 -->
      <inertial>
        <mass>0.001</mass>
        <inertia>
          <ixx>1e-5</ixx>
          <ixy>0.0</ixy>
          <iyy>1e-5</iyy>
          <ixz>0.0</ixz>
          <iyz>0.0</iyz>
          <izz>1e-5</izz>
        </inertia>
      </inertial>

    <visual name="right_flap_visual">
        <geometry>
          <mesh>
            <scale>1 1 1</scale>
            <uri>model://my_tilt_vtol/meshes/U60_Right_Flap.dae</uri>
          </mesh>
        </geometry>
        <material>  <!-- Blue -->
          <ambient>0 1 1 1.0</ambient>
          <diffuse>0 1 1 1.0</diffuse>
        </material>
      </visual>
      <gravity>1</gravity>
      <velocity_decay />
      <self_collide>0</self_collide>
    </link>

    <joint name='right_flap_joint' type='revolute'>
      <child>right_flap</child>
      <parent>base_link</parent>
      <axis>
        <xyz>0 1 0</xyz> <!--Y축 기준 회전 (틸트로터)-->
        <limit>
          <lower>-0.78</lower>
          <upper>0.78</upper> <!--나중에 각도 볼 필요 있음.-->
        </limit>
        <dynamics>
          <damping>1.000</damping>
        </dynamics>
      </axis>
    </joint>

    <link name="left_flap">
      <!-- base_link 기준 위치 -->
      <inertial>
        <mass>0.001</mass>
        <inertia>
          <ixx>1e-5</ixx>
          <ixy>0.0</ixy>
          <iyy>1e-5</iyy>
          <ixz>0.0</ixz>
          <iyz>0.0</iyz>
          <izz>1e-5</izz>
        </inertia>
      </inertial>

    <visual name="left_flap_visual">
        <geometry>
          <mesh>
            <scale>1 1 1</scale>
            <uri>model://my_tilt_vtol/meshes/U60_Left_Flap.dae</uri>
          </mesh>
        </geometry>
        <material>  <!-- Blue -->
          <ambient>0 1 1 1.0</ambient>
          <diffuse>0 1 1 1.0</diffuse>
        </material>
      </visual>
      <gravity>1</gravity>
      <velocity_decay />
      <self_collide>0</self_collide>
    </link>

    <joint name='left_flap_joint' type='revolute'>
      <child>left_flap</child>
      <parent>base_link</parent>
      <axis>
        <xyz>0 1 0</xyz> <!--Y축 기준 회전 (틸트로터)-->
        <limit>
          <lower>-0.78</lower>
          <upper>0.78</upper> <!--나중에 각도 볼 필요 있음.-->
        </limit>
        <dynamics>
          <damping>1.000</damping>
        </dynamics>
      </axis>
    </joint>

    <link name="right_ruddervator">
      <!-- base_link 기준 위치 -->
      <inertial>
        <mass>0.001</mass>
        <inertia>
          <ixx>1e-5</ixx>
          <ixy>0.0</ixy>
          <iyy>1e-5</iyy>
          <ixz>0.0</ixz>
          <iyz>0.0</iyz>
          <izz>1e-5</izz>
        </inertia>
      </inertial>

    <visual name="right_rudder_visual">
        <geometry>
          <mesh>
            <scale>1 1 1</scale>
            <uri>model://my_tilt_vtol/meshes/U60_Right_Ruddervator.dae</uri>
          </mesh>
        </geometry>
        <material>  <!-- Blue -->
          <ambient>0 1 1 1.0</ambient>
          <diffuse>0 1 1 1.0</diffuse>
        </material>
      </visual>
      <gravity>1</gravity>
      <velocity_decay />
      <self_collide>0</self_collide>
    </link>

    <joint name='right_ruddervator_joint' type='revolute'>
      <child>right_ruddervator</child>
      <parent>base_link</parent>
      <axis>
        <xyz>0 1 0</xyz> <!--Y축 기준 회전 (틸트로터)-->
        <limit>
          <lower>-0.78</lower>
          <upper>0.78</upper> <!--나중에 각도 볼 필요 있음.-->
        </limit>
        <dynamics>
          <damping>1.000</damping>
        </dynamics>
      </axis>
    </joint>


    <link name="left_ruddervator">
      <!-- base_link 기준 위치 -->
      <inertial>
        <mass>0.001</mass>
        <inertia>
          <ixx>1e-5</ixx>
          <ixy>0.0</ixy>
          <iyy>1e-5</iyy>
          <ixz>0.0</ixz>
          <iyz>0.0</iyz>
          <izz>1e-5</izz>
        </inertia>
      </inertial>

    <visual name="left_rudder_visual">
        <geometry>
          <mesh>
            <scale>1 1 1</scale>
            <uri>model://my_tilt_vtol/meshes/U60_Left_Ruddervator.dae</uri>
          </mesh>
        </geometry>
        <material>  <!-- Blue -->
          <ambient>0 1 1 1.0</ambient>
          <diffuse>0 1 1 1.0</diffuse>
        </material>
      </visual>
      <gravity>1</gravity>
      <velocity_decay />
      <self_collide>0</self_collide>
    </link>

    <joint name='left_ruddervator_joint' type='revolute'>
      <child>left_ruddervator</child>
      <parent>base_link</parent>
      <axis>
        <xyz>0 1 0</xyz> <!--Y축 기준 회전 (틸트로터)-->
        <limit>
          <lower>-0.78</lower>
          <upper>0.78</upper>
        </limit>
        <dynamics>
          <damping>1.000</damping>
        </dynamics>
      </axis>
    </joint>

  </model>
</sdf>
