<sdf version='1.7'>
  <model name='boat'>
    <link name='base_link'>
      <pose>0 0 0 0 -0 0</pose>
      <inertial>
        <pose >0 0 0.124229 0 -0 0</pose>
        <mass>227</mass>
        <inertia>
          <ixx>181.42</ixx>
          <ixy>0</ixy>
          <ixz>0</ixz>
          <iyy>408.203</iyy>
          <iyz>0</iyz>
          <izz>495.037</izz>
        </inertia>
      </inertial>
      <collision name='base_link_fixed_joint_lump__left_float_collision'>
        <pose >-0.4 1.03 0.2 3.14159 1.57079 3.14159</pose>
        <geometry>
          <cylinder>
            <length>4</length>
            <radius>0.2</radius>
          </cylinder>
        </geometry>
      </collision>
      <collision name='base_link_fixed_joint_lump__left_mid_float_collision_1'>
        <pose>1.85 1.03 0.3 0 1.38 0</pose>
        <geometry>
          <cylinder>
            <length>0.5</length>
            <radius>0.17</radius>
          </cylinder>
        </geometry>
      </collision>
      <collision name='base_link_fixed_joint_lump__left_front_float_collision_2'>
        <pose>2.3 1.03 0.4 0 1.3 0</pose>
        <geometry>
          <cylinder>
            <length>0.45</length>
            <radius>0.12</radius>
          </cylinder>
        </geometry>
      </collision>
      <collision name='base_link_fixed_joint_lump__front_left_beam_lower_collision_3'>
        <pose>0.9 0.85 1 0.78 -0 0</pose>
        <geometry>
          <cylinder>
            <length>0.5</length>
            <radius>0.04</radius>
          </cylinder>
        </geometry>
      </collision>
      <collision name='base_link_fixed_joint_lump__front_left_beam_upper_collision_4'>
        <pose>0.9 0.6 1.18 1.35 -0 0</pose>
        <geometry>
          <cylinder>
            <length>0.2</length>
            <radius>0.04</radius>
          </cylinder>
        </geometry>
      </collision>
      <collision name='base_link_fixed_joint_lump__mid_left_beam_lower_collision_5'>
        <pose>-0.65 0.99 0.7 0.1 0.25 0</pose>
        <geometry>
          <cylinder>
            <length>0.45</length>
            <radius>0.03</radius>
          </cylinder>
        </geometry>
      </collision>
      <collision name='base_link_fixed_joint_lump__mid_left_beam_medium_collision_6'>
        <pose>-0.57 0.87 1.05 0.75 0.25 0</pose>
        <geometry>
          <cylinder>
            <length>0.32</length>
            <radius>0.03</radius>
          </cylinder>
        </geometry>
      </collision>
      <collision name='base_link_fixed_joint_lump__mid_left_beam_upper_collision_7'>
        <pose>-0.55 0.65 1.17 1.35 0.25 0</pose>
        <geometry>
          <cylinder>
            <length>0.3</length>
            <radius>0.03</radius>
          </cylinder>
        </geometry>
      </collision>
      <collision name='base_link_fixed_joint_lump__rear_left_beam_lower_collision_8'>
        <pose>-0.74 1.03 0.7 0 -0.15 0</pose>
        <geometry>
          <cylinder>
            <length>0.45</length>
            <radius>0.03</radius>
          </cylinder>
        </geometry>
      </collision>
      <collision name='base_link_fixed_joint_lump__rear_left_beam_medium_collision_9'>
        <pose>-0.79 0.91 1.05 0.75 -0.15 -0</pose>
        <geometry>
          <cylinder>
            <length>0.32</length>
            <radius>0.03</radius>
          </cylinder>
        </geometry>
      </collision>
      <collision name='base_link_fixed_joint_lump__rear_left_beam_upper_collision_10'>
        <pose>-0.81 0.67 1.18 1.45 -0.15 0</pose>
        <geometry>
          <cylinder>
            <length>0.3</length>
            <radius>0.03</radius>
          </cylinder>
        </geometry>
      </collision>
      <collision name='base_link_fixed_joint_lump__left_joint_collision_11'>
        <pose>0.58 1.03 0.6 0 -0.6 0</pose>
        <geometry>
          <box>
            <size>0.65 0.2 0.1</size>
          </box>
        </geometry>
      </collision>
      <collision name='base_link_fixed_joint_lump__right_float_collision_12'>
        <pose>-0.4 -1.03 0.2 3.14159 1.57079 3.14159</pose>
        <geometry>
          <cylinder>
            <length>4</length>
            <radius>0.2</radius>
          </cylinder>
        </geometry>
      </collision>
      <collision name='base_link_fixed_joint_lump__right_mid_float_collision_13'>
        <pose>1.85 -1.03 0.3 0 1.38 0</pose>
        <geometry>
          <cylinder>
            <length>0.5</length>
            <radius>0.17</radius>
          </cylinder>
        </geometry>
      </collision>
      <collision name='base_link_fixed_joint_lump__right_front_float_collision_14'>
        <pose>2.3 -1.03 0.4 0 1.3 0</pose>
        <geometry>
          <cylinder>
            <length>0.45</length>
            <radius>0.12</radius>
          </cylinder>
        </geometry>
      </collision>
      <collision name='base_link_fixed_joint_lump__front_right_beam_lower_collision_15'>
        <pose>0.9 -0.85 1 -0.78 0 0</pose>
        <geometry>
          <cylinder>
            <length>0.5</length>
            <radius>0.04</radius>
          </cylinder>
        </geometry>
      </collision>
      <collision name='base_link_fixed_joint_lump__front_right_beam_upper_collision_16'>
        <pose>0.9 -0.6 1.18 -1.35 0 0</pose>
        <geometry>
          <cylinder>
            <length>0.2</length>
            <radius>0.04</radius>
          </cylinder>
        </geometry>
      </collision>
      <collision name='base_link_fixed_joint_lump__mid_right_beam_lower_collision_17'>
        <pose>-0.65 -0.99 0.7 -0.1 0.25 0</pose>
        <geometry>
          <cylinder>
            <length>0.45</length>
            <radius>0.03</radius>
          </cylinder>
        </geometry>
      </collision>
      <collision name='base_link_fixed_joint_lump__mid_right_beam_medium_collision_18'>
        <pose>-0.57 -0.87 1.05 -0.75 0.25 0</pose>
        <geometry>
          <cylinder>
            <length>0.32</length>
            <radius>0.03</radius>
          </cylinder>
        </geometry>
      </collision>
      <collision name='base_link_fixed_joint_lump__mid_right_beam_upper_collision_19'>
        <pose>-0.55 -0.65 1.17 -1.35 0.25 0</pose>
        <geometry>
          <cylinder>
            <length>0.3</length>
            <radius>0.03</radius>
          </cylinder>
        </geometry>
      </collision>
      <collision name='base_link_fixed_joint_lump__rear_right_beam_lower_collision_20'>
        <pose>-0.74 -1.03 0.7 0 -0.15 0</pose>
        <geometry>
          <cylinder>
            <length>0.45</length>
            <radius>0.03</radius>
          </cylinder>
        </geometry>
      </collision>
      <collision name='base_link_fixed_joint_lump__rear_right_beam_medium_collision_21'>
        <pose>-0.79 -0.91 1.05 -0.75 -0.15 0</pose>
        <geometry>
          <cylinder>
            <length>0.32</length>
            <radius>0.03</radius>
          </cylinder>
        </geometry>
      </collision>
      <collision name='base_link_fixed_joint_lump__rear_right_beam_upper_collision_22'>
        <pose>-0.81 -0.67 1.18 -1.45 -0.15 0</pose>
        <geometry>
          <cylinder>
            <length>0.3</length>
            <radius>0.03</radius>
          </cylinder>
        </geometry>
      </collision>
      <collision name='base_link_fixed_joint_lump__right_joint_collision_23'>
        <pose>0.58 -1.03 0.6 0 -0.6 0</pose>
        <geometry>
          <box>
            <size>0.65 0.2 0.1</size>
          </box>
        </geometry>
      </collision>
      <collision name='base_link_fixed_joint_lump__top_base_collision_24'>
        <pose>0 0 1.25 0 -0 0</pose>
        <geometry>
          <box>
            <size>1.85 1 0.1</size>
          </box>
        </geometry>
      </collision>
      <collision name='base_link_fixed_joint_lump__left_battery_collision_collision_25'>
        <pose>0 1 0.6 0 -0 0</pose>
        <geometry>
          <box>
            <size>0.6 0.4 0.31</size>
          </box>
        </geometry>
      </collision>
      <collision name='base_link_fixed_joint_lump__right_battery_collision_collision_26'>
        <pose>0 -1 0.6 0 -0 0</pose>
        <geometry>
          <box>
            <size>0.6 0.4 0.31</size>
          </box>
        </geometry>
      </collision>
      <visual name='base_link_fixed_joint_lump__dummy_link_visual'>
        <pose>0 0 0 0 -0 0</pose>
        <geometry>
          <mesh>
            <scale>1 1 1</scale>
            <uri>model://boat/meshes/body.dae</uri>
          </mesh>
        </geometry>
      </visual>
      <visual name='base_link_fixed_joint_lump__left_battery_visual_visual_1'>
        <pose>0 -0.03 0 0 -0 0</pose>
        <geometry>
          <mesh>
            <scale>1 1 1</scale>
            <uri>model://boat/meshes/battery.dae</uri>
          </mesh>
        </geometry>
        <material>
          <ambient>0.3 0.3 0.3 1.0</ambient>
          <diffuse>0.3 0.3 0.3 1.0</diffuse>
        </material>
      </visual>
      <visual name='base_link_fixed_joint_lump__right_battery_visual_visual_2'>
        <pose>0 -2.03 0 0 -0 0</pose>
        <geometry>
          <mesh>
            <scale>1 1 1</scale>
            <uri>model://boat/meshes/battery.dae</uri>
          </mesh>
        </geometry>
        <material>
          <ambient>0.3 0.3 0.3 1.0</ambient>
          <diffuse>0.3 0.3 0.3 1.0</diffuse>
        </material>
      </visual>
      <visual name='right_engine_link_visual'>
        <pose>-2.37378 -1.02713 0.318237 0 -0 0</pose>
        <geometry>
          <mesh>
            <scale>1 1 1</scale>
            <uri>model://boat/meshes//engine.dae</uri>
          </mesh>
        </geometry>
      </visual>
      <visual name='left_engine_link_visual'>
        <pose>-2.37378 1.02713 0.318237 0 -0 0</pose>
        <geometry>
          <mesh>
            <scale>1 1 1</scale>
            <uri>model://boat/meshes//engine.dae</uri>
          </mesh>
        </geometry>
      </visual>
      <sensor name="imu_sensor" type="imu">
        <always_on>1</always_on>
        <update_rate>250</update_rate>
        <imu>
          <angular_velocity>
            <x>
              <noise type="gaussian">
                <mean>0</mean>
                <stddev>0.0003394</stddev>
                <dynamic_bias_stddev>3.8785e-05</dynamic_bias_stddev>
                <dynamic_bias_correlation_time>1000</dynamic_bias_correlation_time>
              </noise>
            </x>
            <y>
              <noise type="gaussian">
                <mean>0</mean>
                <stddev>0.0003394</stddev>
                <dynamic_bias_stddev>3.8785e-05</dynamic_bias_stddev>
                <dynamic_bias_correlation_time>1000</dynamic_bias_correlation_time>
              </noise>
            </y>
            <z>
              <noise type="gaussian">
                <mean>0</mean>
                <stddev>0.0003394</stddev>
                <dynamic_bias_stddev>3.8785e-05</dynamic_bias_stddev>
                <dynamic_bias_correlation_time>1000</dynamic_bias_correlation_time>
              </noise>
            </z>
          </angular_velocity>
          <linear_acceleration>
            <x>
              <noise type="gaussian">
                <mean>0</mean>
                <stddev>0.004</stddev>
                <dynamic_bias_stddev>0.006</dynamic_bias_stddev>
                <dynamic_bias_correlation_time>300</dynamic_bias_correlation_time>
              </noise>
            </x>
            <y>
              <noise type="gaussian">
                <mean>0</mean>
                <stddev>0.004</stddev>
                <dynamic_bias_stddev>0.006</dynamic_bias_stddev>
                <dynamic_bias_correlation_time>300</dynamic_bias_correlation_time>
              </noise>
            </y>
            <z>
              <noise type="gaussian">
                <mean>0</mean>
                <stddev>0.004</stddev>
                <dynamic_bias_stddev>0.006</dynamic_bias_stddev>
                <dynamic_bias_correlation_time>300</dynamic_bias_correlation_time>
              </noise>
            </z>
          </linear_acceleration>
        </imu>
      </sensor>
      <sensor name="air_pressure_sensor" type="air_pressure">
        <always_on>1</always_on>
        <update_rate>50</update_rate>
        <air_pressure>
          <pressure>
            <noise type="gaussian">
              <mean>0</mean>
              <stddev>0.01</stddev>
            </noise>
          </pressure>
        </air_pressure>
      </sensor>
      <sensor name="magnetometer_sensor" type="magnetometer">
        <always_on>1</always_on>
        <update_rate>100</update_rate>
        <magnetometer>
          <x>
            <noise type="gaussian">
              <stddev>0.0001</stddev>
            </noise>
          </x>
          <y>
            <noise type="gaussian">
              <stddev>0.0001</stddev>
            </noise>
          </y>
          <z>
            <noise type="gaussian">
              <stddev>0.0001</stddev>
            </noise>
          </z>
        </magnetometer>
      </sensor>
      <sensor name="navsat_sensor" type="navsat">
        <always_on>1</always_on>
        <update_rate>30</update_rate>
      </sensor>
    </link>
    <link name='left_propeller_link'>
      <pose>-2.65193 1.02713 -0.191134 0 1.57079 0</pose>
      <inertial>
        <pose>0 0 0 0 -0 0</pose>
        <mass>0.5</mass>
        <inertia>
          <ixx>0.008545</ixx>
          <ixy>0</ixy>
          <ixz>0</ixz>
          <iyy>0.008545</iyy>
          <iyz>0</iyz>
          <izz>0.0144</izz>
        </inertia>
      </inertial>
      <collision name='left_propeller_link_fixed_joint_lump__left_propeller_collision_collision'>
        <pose>-0.08 0 0 3.14159 0.0 3.14159</pose>
        <geometry>
          <cylinder>
            <length>0.18</length>
            <radius>0.24</radius>
          </cylinder>
        </geometry>
      </collision>
      <visual name='left_propeller_link_visual'>
        <pose>0 0 0 0 -1.57079 0</pose>
        <geometry>
          <mesh>
            <scale>1 1 1</scale>
            <uri>model://boat/meshes/propeller.dae</uri>
          </mesh>
        </geometry>
      </visual>
    </link>
    <joint name='left_engine_propeller_joint' type='revolute'>
      <child>left_propeller_link</child>
      <parent>base_link</parent>
      <axis>
        <xyz>0 0 1</xyz>
        <limit>
          <lower>-1e+16</lower>
          <upper>1e+16</upper>
        </limit>
        <dynamics>
          <!-- <damping>0.05</damping>
          <friction>0.05</friction> -->
          <spring_reference>0</spring_reference>
          <spring_stiffness>0</spring_stiffness>
        </dynamics>
      </axis>
    </joint>
    <link name='right_propeller_link'>
      <pose>-2.65193 -1.02713 -0.191134 0 1.57079 0</pose>
      <inertial>
        <pose>0 0 0 0 -0 0</pose>
        <mass>0.5</mass>
        <inertia>
          <ixx>0.008545</ixx>
          <ixy>0</ixy>
          <ixz>0</ixz>
          <iyy>0.008545</iyy>
          <iyz>0</iyz>
          <izz>0.0144</izz>
        </inertia>
      </inertial>
      <collision name='right_propeller_link_fixed_joint_lump__right_propeller_collision_collision'>
        <pose>-0.08 0 0 3.14159 0.0 3.14159</pose>
        <geometry>
          <cylinder>
            <length>0.18</length>
            <radius>0.24</radius>
          </cylinder>
        </geometry>
      </collision>
      <visual name='right_propeller_link_visual'>
        <pose>0 0 0 0 -1.57079 0</pose>
        <geometry>
          <mesh>
            <scale>1 1 1</scale>
            <uri>model://boat/meshes/propeller.dae</uri>
          </mesh>
        </geometry>
      </visual>
    </link>
    <joint name='right_engine_propeller_joint' type='revolute'>
      <child>right_propeller_link</child>
      <parent>base_link</parent>
      <axis>
        <xyz>0 0 1</xyz>
        <limit>
          <lower>-1e+16</lower>
          <upper>1e+16</upper>
        </limit>
        <dynamics>
          <!-- <damping>0.05</damping>
          <friction>0.05</friction> -->
          <spring_reference>0</spring_reference>
          <spring_stiffness>0</spring_stiffness>
        </dynamics>
      </axis>
    </joint>
    <static>0</static>
    <plugin filename="gz-sim-multicopter-motor-model-system" name="gz::sim::systems::MulticopterMotorModel">
      <jointName>left_engine_propeller_joint</jointName>
      <linkName>left_propeller_link</linkName>
      <turningDirection>cw</turningDirection>
      <timeConstantUp>0.0125</timeConstantUp>
      <timeConstantDown>0.025</timeConstantDown>
      <maxRotVelocity>1100</maxRotVelocity>
      <motorConstant>8.54858e-02</motorConstant>
      <momentConstant>0.01</momentConstant>
      <commandSubTopic>command/motor_speed</commandSubTopic>
      <motorNumber>0</motorNumber>
      <rotorDragCoefficient>0.000806428</rotorDragCoefficient>
      <rollingMomentCoefficient>1e-06</rollingMomentCoefficient>
      <rotorVelocitySlowdownSim>10</rotorVelocitySlowdownSim>
      <motorType>velocity</motorType>
    </plugin>
    <plugin filename="gz-sim-multicopter-motor-model-system" name="gz::sim::systems::MulticopterMotorModel">
      <jointName>right_engine_propeller_joint</jointName>
      <linkName>right_propeller_link</linkName>
      <turningDirection>cw</turningDirection>
      <timeConstantUp>0.0125</timeConstantUp>
      <timeConstantDown>0.025</timeConstantDown>
      <maxRotVelocity>1100</maxRotVelocity>
      <motorConstant>8.54858e-02</motorConstant>
      <momentConstant>0.01</momentConstant>
      <commandSubTopic>command/motor_speed</commandSubTopic>
      <motorNumber>1</motorNumber>
      <rotorDragCoefficient>0.000806428</rotorDragCoefficient>
      <rollingMomentCoefficient>1e-06</rollingMomentCoefficient>
      <rotorVelocitySlowdownSim>10</rotorVelocitySlowdownSim>
      <motorType>velocity</motorType>
    </plugin>
    <plugin filename="libUsivDynamicsPlugin.so" name="custom::UsvDynamics">
      <bodyName>base_link</bodyName>

      <!-- Hull geometry - match Gazebo Classic exactly -->
      <boatLength>4.9</boatLength>
      <boatWidth>2.4</boatWidth>
      <hullRadius>0.213</hullRadius>
      <length_n>2</length_n>

      <!-- Environmental parameters - match Gazebo Classic exactly -->
      <waterLevel>0</waterLevel>
      <waterDensity>997.8</waterDensity>

      <!-- Added mass coefficients - match Gazebo Classic exactly -->
      <xDotU>0.0</xDotU>
      <yDotV>0.0</yDotV>
      <nDotR>0.0</nDotR>

      <!-- Linear drag coefficients - match Gazebo Classic exactly -->
      <xU>51.3</xU>
      <yV>102.6</yV>
      <zW>500.0</zW>
      <kP>50.0</kP>
      <mQ>50.0</mQ>
      <nR>400.0</nR>

      <!-- Quadratic drag coefficients - match Gazebo Classic exactly -->
      <xUU>72.4</xUU>
      <yVV>0.0</yVV>
      <nRR>0.0</nRR>
    </plugin>
  </model>
</sdf>
