<sdf version='1.6'>
  <model name='boat'>
    <link name='base_link'>
      <pose>0 0 0 0 -0 0</pose>
      <inertial>
        <pose >0 0 0.124229 0 -0 0</pose>
        <mass>227</mass>
        <inertia>
          <ixx>181.42</ixx>
          <ixy>0</ixy>
          <ixz>0</ixz>
          <iyy>408.203</iyy>
          <iyz>0</iyz>
          <izz>495.037</izz>
        </inertia>
      </inertial>
      <collision name='base_link_fixed_joint_lump__left_float_collision'>
        <pose >-0.4 1.03 0.2 3.14159 1.57079 3.14159</pose>
        <geometry>
          <cylinder>
            <length>4</length>
            <radius>0.2</radius>
          </cylinder>
        </geometry>
      </collision>
      <collision name='base_link_fixed_joint_lump__left_mid_float_collision_1'>
        <pose>1.85 1.03 0.3 0 1.38 0</pose>
        <geometry>
          <cylinder>
            <length>0.5</length>
            <radius>0.17</radius>
          </cylinder>
        </geometry>
      </collision>
      <collision name='base_link_fixed_joint_lump__left_front_float_collision_2'>
        <pose>2.3 1.03 0.4 0 1.3 0</pose>
        <geometry>
          <cylinder>
            <length>0.45</length>
            <radius>0.12</radius>
          </cylinder>
        </geometry>
      </collision>
      <collision name='base_link_fixed_joint_lump__front_left_beam_lower_collision_3'>
        <pose>0.9 0.85 1 0.78 -0 0</pose>
        <geometry>
          <cylinder>
            <length>0.5</length>
            <radius>0.04</radius>
          </cylinder>
        </geometry>
      </collision>
      <collision name='base_link_fixed_joint_lump__front_left_beam_upper_collision_4'>
        <pose>0.9 0.6 1.18 1.35 -0 0</pose>
        <geometry>
          <cylinder>
            <length>0.2</length>
            <radius>0.04</radius>
          </cylinder>
        </geometry>
      </collision>
      <collision name='base_link_fixed_joint_lump__mid_left_beam_lower_collision_5'>
        <pose>-0.65 0.99 0.7 0.1 0.25 0</pose>
        <geometry>
          <cylinder>
            <length>0.45</length>
            <radius>0.03</radius>
          </cylinder>
        </geometry>
      </collision>
      <collision name='base_link_fixed_joint_lump__mid_left_beam_medium_collision_6'>
        <pose>-0.57 0.87 1.05 0.75 0.25 0</pose>
        <geometry>
          <cylinder>
            <length>0.32</length>
            <radius>0.03</radius>
          </cylinder>
        </geometry>
      </collision>
      <collision name='base_link_fixed_joint_lump__mid_left_beam_upper_collision_7'>
        <pose>-0.55 0.65 1.17 1.35 0.25 0</pose>
        <geometry>
          <cylinder>
            <length>0.3</length>
            <radius>0.03</radius>
          </cylinder>
        </geometry>
      </collision>
      <collision name='base_link_fixed_joint_lump__rear_left_beam_lower_collision_8'>
        <pose>-0.74 1.03 0.7 0 -0.15 0</pose>
        <geometry>
          <cylinder>
            <length>0.45</length>
            <radius>0.03</radius>
          </cylinder>
        </geometry>
      </collision>
      <collision name='base_link_fixed_joint_lump__rear_left_beam_medium_collision_9'>
        <pose>-0.79 0.91 1.05 0.75 -0.15 -0</pose>
        <geometry>
          <cylinder>
            <length>0.32</length>
            <radius>0.03</radius>
          </cylinder>
        </geometry>
      </collision>
      <collision name='base_link_fixed_joint_lump__rear_left_beam_upper_collision_10'>
        <pose>-0.81 0.67 1.18 1.45 -0.15 0</pose>
        <geometry>
          <cylinder>
            <length>0.3</length>
            <radius>0.03</radius>
          </cylinder>
        </geometry>
      </collision>
      <collision name='base_link_fixed_joint_lump__left_joint_collision_11'>
        <pose>0.58 1.03 0.6 0 -0.6 0</pose>
        <geometry>
          <box>
            <size>0.65 0.2 0.1</size>
          </box>
        </geometry>
      </collision>
      <collision name='base_link_fixed_joint_lump__right_float_collision_12'>
        <pose>-0.4 -1.03 0.2 3.14159 1.57079 3.14159</pose>
        <geometry>
          <cylinder>
            <length>4</length>
            <radius>0.2</radius>
          </cylinder>
        </geometry>
      </collision>
      <collision name='base_link_fixed_joint_lump__right_mid_float_collision_13'>
        <pose>1.85 -1.03 0.3 0 1.38 0</pose>
        <geometry>
          <cylinder>
            <length>0.5</length>
            <radius>0.17</radius>
          </cylinder>
        </geometry>
      </collision>
      <collision name='base_link_fixed_joint_lump__right_front_float_collision_14'>
        <pose>2.3 -1.03 0.4 0 1.3 0</pose>
        <geometry>
          <cylinder>
            <length>0.45</length>
            <radius>0.12</radius>
          </cylinder>
        </geometry>
      </collision>
      <collision name='base_link_fixed_joint_lump__front_right_beam_lower_collision_15'>
        <pose>0.9 -0.85 1 -0.78 0 0</pose>
        <geometry>
          <cylinder>
            <length>0.5</length>
            <radius>0.04</radius>
          </cylinder>
        </geometry>
      </collision>
      <collision name='base_link_fixed_joint_lump__front_right_beam_upper_collision_16'>
        <pose>0.9 -0.6 1.18 -1.35 0 0</pose>
        <geometry>
          <cylinder>
            <length>0.2</length>
            <radius>0.04</radius>
          </cylinder>
        </geometry>
      </collision>
      <collision name='base_link_fixed_joint_lump__mid_right_beam_lower_collision_17'>
        <pose>-0.65 -0.99 0.7 -0.1 0.25 0</pose>
        <geometry>
          <cylinder>
            <length>0.45</length>
            <radius>0.03</radius>
          </cylinder>
        </geometry>
      </collision>
      <collision name='base_link_fixed_joint_lump__mid_right_beam_medium_collision_18'>
        <pose>-0.57 -0.87 1.05 -0.75 0.25 0</pose>
        <geometry>
          <cylinder>
            <length>0.32</length>
            <radius>0.03</radius>
          </cylinder>
        </geometry>
      </collision>
      <collision name='base_link_fixed_joint_lump__mid_right_beam_upper_collision_19'>
        <pose>-0.55 -0.65 1.17 -1.35 0.25 0</pose>
        <geometry>
          <cylinder>
            <length>0.3</length>
            <radius>0.03</radius>
          </cylinder>
        </geometry>
      </collision>
      <collision name='base_link_fixed_joint_lump__rear_right_beam_lower_collision_20'>
        <pose>-0.74 -1.03 0.7 0 -0.15 0</pose>
        <geometry>
          <cylinder>
            <length>0.45</length>
            <radius>0.03</radius>
          </cylinder>
        </geometry>
      </collision>
      <collision name='base_link_fixed_joint_lump__rear_right_beam_medium_collision_21'>
        <pose>-0.79 -0.91 1.05 -0.75 -0.15 0</pose>
        <geometry>
          <cylinder>
            <length>0.32</length>
            <radius>0.03</radius>
          </cylinder>
        </geometry>
      </collision>
      <collision name='base_link_fixed_joint_lump__rear_right_beam_upper_collision_22'>
        <pose>-0.81 -0.67 1.18 -1.45 -0.15 0</pose>
        <geometry>
          <cylinder>
            <length>0.3</length>
            <radius>0.03</radius>
          </cylinder>
        </geometry>
      </collision>
      <collision name='base_link_fixed_joint_lump__right_joint_collision_23'>
        <pose>0.58 -1.03 0.6 0 -0.6 0</pose>
        <geometry>
          <box>
            <size>0.65 0.2 0.1</size>
          </box>
        </geometry>
      </collision>
      <collision name='base_link_fixed_joint_lump__top_base_collision_24'>
        <pose>0 0 1.25 0 -0 0</pose>
        <geometry>
          <box>
            <size>1.85 1 0.1</size>
          </box>
        </geometry>
      </collision>
      <collision name='base_link_fixed_joint_lump__left_battery_collision_collision_25'>
        <pose>0 1 0.6 0 -0 0</pose>
        <geometry>
          <box>
            <size>0.6 0.4 0.31</size>
          </box>
        </geometry>
      </collision>
      <collision name='base_link_fixed_joint_lump__right_battery_collision_collision_26'>
        <pose>0 -1 0.6 0 -0 0</pose>
        <geometry>
          <box>
            <size>0.6 0.4 0.31</size>
          </box>
        </geometry>
      </collision>
      <visual name='base_link_fixed_joint_lump__dummy_link_visual'>
        <pose>0 0 0 0 -0 0</pose>
        <geometry>
          <mesh>
            <scale>1 1 1</scale>
            <uri>model://boat/meshes/body.dae</uri>
          </mesh>
        </geometry>
      </visual>
      <visual name='base_link_fixed_joint_lump__left_battery_visual_visual_1'>
        <pose>0 -0.03 0 0 -0 0</pose>
        <geometry>
          <mesh>
            <scale>1 1 1</scale>
            <uri>model://boat/meshes/battery.dae</uri>
          </mesh>
        </geometry>
      </visual>
      <visual name='base_link_fixed_joint_lump__right_battery_visual_visual_2'>
        <pose>0 -2.03 0 0 -0 0</pose>
        <geometry>
          <mesh>
            <scale>1 1 1</scale>
            <uri>model://boat/meshes/battery.dae</uri>
          </mesh>
        </geometry>
      </visual>
      <sensor name="air_pressure_sensor" type="air_pressure">
        <gz_frame_id>base_link</gz_frame_id>
        <always_on>1</always_on>
        <update_rate>50</update_rate>
        <air_pressure>
          <!-- Noise modeled after BMP390 -->
          <pressure>
            <noise type="gaussian">
              <mean>0</mean>
              <stddev>3</stddev>
            </noise>
          </pressure>
        </air_pressure>
      </sensor>
      <sensor name="magnetometer_sensor" type="magnetometer">
        <gz_frame_id>base_link</gz_frame_id>
        <always_on>1</always_on>
        <update_rate>100</update_rate>
        <magnetometer>
          <!-- TODO: update to fix units and coordinate system when we move past Harmonic -->
          <!-- See https://github.com/gazebosim/gz-sim/pull/2460 -->
          <!-- 3mgauss RMS: NOTE: noise is in tesla but sensor reports data in gauss -->
          <!-- Noise modeled after IIS2MDC -->
          <x>
            <noise type="gaussian">
              <stddev>0.0001</stddev>
            </noise>
          </x>
          <y>
            <noise type="gaussian">
              <stddev>0.0001</stddev>
            </noise>
          </y>
          <z>
            <noise type="gaussian">
              <stddev>0.0001</stddev>
            </noise>
          </z>
        </magnetometer>
      </sensor>
      <sensor name="imu_sensor" type="imu">
        <gz_frame_id>base_link</gz_frame_id>
        <always_on>1</always_on>
        <update_rate>250</update_rate>
        <imu>
          <angular_velocity>
            <!-- Noise modeled after IIM42653 -->
            <!-- 0.05 deg/s converted to rad/s -->
            <x>
              <noise type="gaussian">
                <mean>0.0</mean>
                <stddev>0.0008726646</stddev>
              </noise>
            </x>
            <y>
              <noise type="gaussian">
                <mean>0.0</mean>
                <stddev>0.0008726646</stddev>
              </noise>
            </y>
            <z>
              <noise type="gaussian">
                <mean>0.0</mean>
                <stddev>0.0008726646</stddev>
              </noise>
            </z>
          </angular_velocity>
          <linear_acceleration>
            <!-- Noise modeled after IIM42653 -->
            <!-- X & Y axis: 0.65 mg-rms converted to m/ss -->
            <x>
              <noise type="gaussian">
                <mean>0.0</mean>
                <stddev>0.00637</stddev>
              </noise>
            </x>
            <y>
              <noise type="gaussian">
                <mean>0.0</mean>
                <stddev>0.00637</stddev>
              </noise>
            </y>
            <!-- Z axis: 0.70 mg-rms converted to m/ss-->
            <z>
              <noise type="gaussian">
                <mean>0.0</mean>
                <stddev>0.00686</stddev>
              </noise>
            </z>
          </linear_acceleration>
        </imu>
      </sensor>
      <sensor name="navsat_sensor" type="navsat">
        <gz_frame_id>base_link</gz_frame_id>
        <always_on>1</always_on>
        <update_rate>30</update_rate>
      </sensor>
    </link>

    <!-- Left engine chain-->
    <joint name='left_engine_joint' type='revolute'>
      <child>left_engine_link</child>
      <parent>base_link</parent>
      <pose relative_to="base_link">-2.37378 1.02713 0.318237 0 -0 0</pose>
      <axis>
        <xyz>0 0 1</xyz>
        <limit>
          <lower>-6.283185</lower>
          <upper>6.283185</upper>
        </limit>
        <dynamics>
          <friction>0.02</friction>
          <spring_reference>0</spring_reference>
          <spring_stiffness>0</spring_stiffness>
        </dynamics>
      </axis>
    </joint>
    <link name='left_engine_link'>
      <pose relative_to='left_engine_joint'>0 0 0 0 0 0</pose>
      <inertial>
        <mass>1</mass>
        <inertia>
          <ixx>0.04</ixx>
          <ixy>0</ixy>
          <ixz>0</ixz>
          <iyy>0.04</iyy>
          <iyz>0</iyz>
          <izz>0.04</izz>
        </inertia>
      </inertial>
      <visual name='left_engine_link_visual'>
        <pose>0 0 0 0 0 0</pose>
        <geometry>
          <mesh>
            <scale>1 1 1</scale>
            <uri>model://boat/meshes//engine.dae</uri>
          </mesh>
        </geometry>
      </visual>
    </link>

    <joint name='left_engine_propeller_joint' type='revolute'>
      <child>left_propeller_link</child>
      <parent>left_engine_link</parent>
      <pose relative_to='left_engine_link'>-0.27815 0  -0.509371 0 1.57079 0</pose>
      <axis>
        <xyz>1 0 0</xyz>
        <limit>
          <lower>-1.79769e+308</lower>
          <upper>1.79769e+308</upper>
        </limit>
        <dynamics>
          <spring_reference>0</spring_reference>
          <spring_stiffness>0</spring_stiffness>
        </dynamics>
        <use_parent_model_frame>1</use_parent_model_frame>
      </axis>
    </joint>
    <link name='left_propeller_link'>
      <pose relative_to='left_engine_propeller_joint'>0 0 0 0 0 0 </pose>
      <inertial>
        <pose>0 0 0 0 -0 0</pose>
        <mass>0.5</mass>
        <inertia>
          <ixx>0.008545</ixx>
          <ixy>0</ixy>
          <ixz>0</ixz>
          <iyy>0.008545</iyy>
          <iyz>0</iyz>
          <izz>0.0144</izz>
        </inertia>
      </inertial>
      <collision name='left_propeller_link__collision'>
        <pose>-0.08 0 0 3.14159 0.0 3.14159</pose>
        <geometry>
          <cylinder>
            <length>0.18</length>
            <radius>0.24</radius>
          </cylinder>
        </geometry>
      </collision>
      <visual name='left_propeller_link_visual'>
        <pose>0 0 0 0 -1.57079 0</pose>
        <geometry>
          <mesh>
            <scale>1 1 1</scale>
            <uri>model://boat/meshes/propeller.dae</uri>
          </mesh>
        </geometry>
      </visual>
    </link>

    <!-- Right engine chain-->
    <joint name='right_engine_joint' type='revolute'>
      <child>right_engine_link</child>
      <parent>base_link</parent>
      <pose relative_to="base_link">-2.37378 -1.02713 0.318237 0 0 0</pose>
      <axis>
        <xyz>0 0 1</xyz>
        <limit>
          <lower>-6.283185</lower>
          <upper>6.283185</upper>
        </limit>
        <dynamics>
          <friction>0.02</friction>
          <spring_reference>0</spring_reference>
          <spring_stiffness>0</spring_stiffness>
        </dynamics>
      </axis>
    </joint>
    <link name='right_engine_link'>
      <pose relative_to='right_engine_joint'>0 0 0 0 0 0</pose>
      <inertial>
        <mass>1</mass>
        <inertia>
          <ixx>0.04</ixx>
          <ixy>0</ixy>
          <ixz>0</ixz>
          <iyy>0.04</iyy>
          <iyz>0</iyz>
          <izz>0.04</izz>
        </inertia>
      </inertial>
      <visual name='right_engine_link_visual'>
        <pose>0 0 0 0 0 0</pose>
        <geometry>
          <mesh>
            <scale>1 1 1</scale>
            <uri>model://boat/meshes/engine.dae</uri>
          </mesh>
        </geometry>
      </visual>
    </link>

    <joint name='right_engine_propeller_joint' type='revolute'>
      <child>right_propeller_link</child>
      <parent>right_engine_link</parent>
      <pose relative_to='right_engine_link'>-0.27815 0  -0.509371 0 1.57079 0</pose>
      <axis>
        <xyz>1 0 0</xyz>
        <limit>
          <lower>-1.79769e+308</lower>
          <upper>1.79769e+308</upper>
        </limit>
        <dynamics>
          <spring_reference>0</spring_reference>
          <spring_stiffness>0</spring_stiffness>
        </dynamics>
        <use_parent_model_frame>1</use_parent_model_frame>
      </axis>
    </joint>
    <link name='right_propeller_link'>
      <pose relative_to='right_engine_propeller_joint'>0 0 0 0 0 0</pose>
      <inertial>
        <pose>0 0 0 0 -0 0</pose>
        <mass>0.5</mass>
        <inertia>
          <ixx>0.008545</ixx>
          <ixy>0</ixy>
          <ixz>0</ixz>
          <iyy>0.008545</iyy>
          <iyz>0</iyz>
          <izz>0.0144</izz>
        </inertia>
      </inertial>
      <collision name='right_propeller_link_collision'>
        <pose>-0.08 0 0 3.14159 0.0 3.14159</pose>
        <geometry>
          <cylinder>
            <length>0.18</length>
            <radius>0.24</radius>
          </cylinder>
        </geometry>
      </collision>
      <visual name='right_propeller_link_visual'>
        <pose>0 0 0 0 -1.57079 0</pose>
        <geometry>
          <mesh>
            <scale>1 1 1</scale>
            <uri>model://boat/meshes/propeller.dae</uri>
          </mesh>
        </geometry>
      </visual>
    </link>

    <!-- Plugins for servo controller: rotates thrusters -->
    <plugin
      filename="gz-sim-joint-position-controller-system"
      name="gz::sim::systems::JointPositionController">
      <joint_name>left_engine_joint</joint_name>
      <sub_topic>servo_0</sub_topic>
      <p_gain>10.0</p_gain>
    </plugin>
    <plugin
      filename="gz-sim-joint-position-controller-system"
      name="gz::sim::systems::JointPositionController">
      <joint_name>right_engine_joint</joint_name>
      <sub_topic>servo_0</sub_topic>
      <p_gain>10.0</p_gain>
    </plugin>

     <!-- Plugins for motor controller: generates thrust -->
     <plugin filename="libGenericMotorModelPlugin.so" name="gz::sim::systems::GenericMotorModel">
        <jointName>left_engine_propeller_joint</jointName>
        <linkName>left_propeller_link</linkName>
        <motorNumber>0</motorNumber>
        <turningDirection>ccw</turningDirection>
        <timeConstantUp>0.0125</timeConstantUp>
        <timeConstantDown>0.025</timeConstantDown>
        <maxRotVelocity>1100.0</maxRotVelocity>
        <motorConstant>10</motorConstant>
        <momentConstant>0.01</momentConstant>
        <commandSubTopic>command/motor_speed</commandSubTopic>
        <rotorDragCoefficient>0</rotorDragCoefficient>
        <rollingMomentCoefficient>0</rollingMomentCoefficient>
        <rotorVelocitySlowdownSim>0.025</rotorVelocitySlowdownSim>
        <motorType>force_polynomial</motorType>
        <controlMethod>duty_cycle</controlMethod>
        <minCommand>0.00</minCommand>
        <minDutyCycle>1100</minDutyCycle>
        <maxDutyCycle>1900</maxDutyCycle>
        <bidirectionalMotor>1</bidirectionalMotor>
        <positiveThrustPolynomial>[0.0, 4.53, 0.0, 0.0, 0.0, 0.0]</positiveThrustPolynomial>
        <negativeThrustPolynomial>[0.0, 3.52, 0.0, 0.0, 0.0, 0.0]</negativeThrustPolynomial>
      </plugin>
      <plugin filename="libGenericMotorModelPlugin.so" name="gz::sim::systems::GenericMotorModel">
        <jointName>right_engine_propeller_joint</jointName>
        <linkName>right_propeller_link</linkName>
        <motorNumber>1</motorNumber>
        <turningDirection>ccw</turningDirection>
        <timeConstantUp>0.0125</timeConstantUp>
        <timeConstantDown>0.025</timeConstantDown>
        <maxRotVelocity>1100.0</maxRotVelocity>
        <motorConstant>10</motorConstant>
        <momentConstant>0.01</momentConstant>
        <commandSubTopic>command/motor_speed</commandSubTopic>
        <rotorDragCoefficient>0</rotorDragCoefficient>
        <rollingMomentCoefficient>0</rollingMomentCoefficient>
        <rotorVelocitySlowdownSim>0.025</rotorVelocitySlowdownSim>
        <motorType>force_polynomial</motorType>
        <controlMethod>duty_cycle</controlMethod>
        <minCommand>0.00</minCommand>
        <minDutyCycle>1100</minDutyCycle>
        <maxDutyCycle>1900</maxDutyCycle>
        <bidirectionalMotor>1</bidirectionalMotor>
        <positiveThrustPolynomial>[0.0, 4.53, 0.0, 0.0, 0.0, 0.0]</positiveThrustPolynomial>
        <negativeThrustPolynomial>[0.0, 3.52, 0.0, 0.0, 0.0, 0.0]</negativeThrustPolynomial>
    </plugin>
  </model>
</sdf>
